Workbook
Name diploma: #REF!

Sheet Menu
A2: AKREDITASI INSTITUSI PERGURUAN TINGGI BARU
A3: TAHUN 2023
C6: Nama Badan Penyelenggara | G6: : | H6: Yayasan Ibnu Atha’illah
C8: Bentuk Perguruan Tinggi | G8: : | H8: Institut
C10: Kode Panel | G10: :
B13: ASESMEN KECUKUPAN | N13: ASESMEN LAPANGAN
B14: (Penilaian Perorangan) | N14: (Penilaian Tim)
B16: Nama Asesor | E16: : | F16: Prof. Dr. Ramdani Wahyu S | N16: Nama Asesor 1 | Q16: : | R16: Prof. Dr. Ramdani Wahyu Sururie
B18: Kota Penilaian | E18: : | F18: Bandung | N18: Nama Asesor 2 | Q18: : | R18: Prof. Dr. Fauzan, MA
B20: Tanggal Penilaian | E20: : | F20: 12 Mei 2026 | N20: Nama Asesor 3 | Q20: :
N22: Kota Penilaian | Q22: : | R22: Sungai Hulu Selatan
N24: Tanggal Penilaian | Q24: : | R24: 24 Mei 2026
B25: ban-pt | C25: v 11.06.2016
B31: Universitas
B32: Institut
B33: Sekolah Tinggi
B34: Politeknik
B35: Akademi

Sheet hitung_F1
A1: INSTRUMEN AKREDITASI INSTITUSI PERGURUAN TINGGI BARU
A2: SEL YANG DIISI HANYA YANG BERWARNA KUNING
A3: NO. | B3: BUTIR | C3: KETERANGAN | E3: SKOR, YA/TIDAK | G3: INFORMASI DARI INSTRUMEN PERGURUAN TINGGI BARU
A4: 1 | B4: 1.1 | C4: Kejelasan, kerealistikan, dan keterkaitan antar visi, misi, tujuan dan sasaran perguruan tinggi yang akan didirikan, dan pemangku kepentingan yang terlibat. | G4: Penyusunan Visi, Misi, Tujuan, dan Sasaran Pendirian Institut Agama Islam (IAI) Guru Kapuh Ibnu Atha’illah (GHIBTA) dilakukan berdasarkan kajian terhadap tantangan serta kebutuhan yang muncul baik dari lingkungan eksternal maupun internal lembaga. Visi IAI: Menjadi Institut Agama Islam Guru Kapuh Ibnu Atha’illah Yang Unggul dalam memadukan keimanan, nilai Qur’an, adab dan keilmuan serta melahirkan generasi yang berdaya guna bagi umat dan berjiwa entrepreneur. Dalam penyusunan sudah melibatkan pihak internal dan eksternal, spt: Pondok Pesantren (Induk/Afiliasi), Pengguna Lulusan (Alumni & Dunia Kerja), Pemerintah (Kemenag, LLDIKTI, Pemda), Masyarakat/Komunitas Lokal, dan Mitra Kerja Sama (Perguruan Tinggi, NGO & Bank Syariah). Secara konseptual sudah ada kelajalasan arah visi yg diharapkan. Visi cukup realitisk karena adanya dukungan SDM dosen tendik yg memadai, ketersedian sarpras pendukung, serta tata kelola kelembagaan yg disiapkan, Konsep Visi memiliki keterkaitan arah dg mimpi atau keinginan Yayasan, yakni melahirkan generasi unggul yg berilmu pengetahuan, berakhlak al-karimah, dan mampu mengadaptasi perkembangan zaman
D5: Skor keterlibatan pemangku kepentingan (0 - 4) | E5: 3 | F5: =IF(E5>4,"Salah isi","")
D6: Skor kejelasan (0 - 4) | E6: 3 | F6: =IF(E6>4,"Salah isi","")
D7: Skor kerealistikan (0 - 4) | E7: 3 | F7: =IF(E7>4,"Salah isi","")
D8: Skor keterkaitan (0 - 4) | E8: 3 | F8: =IF(E8>4,"Salah isi","")
D9: Rata-rata | E9: =AVERAGE(E5:E8) -> 3
C10: Skor | E10: =E9 -> 3
A12: 2 | B12: 1.2 | C12: Perguruan tinggi yang akan didirikan menetapkan rancangan tonggak-tonggak capaian tujuan dengan rentang waktu 5 atau 10 tahun ke depan. | G12: Rencana Induk Pengembangan (RIP) IAI Guru Kapuh Ibnu Atha’illah (GHIBTA) 2025–2047 dijelaskan arah pengembangan lembaga menuju visi tahun 2047 dengan uraian sebagai berikut: Pertama, Tahap Forming, Established Institute. tahun 2032 IAI Guru Kapuh Ibnu Atha’illah (GHIBTA) bertransformasi menjadi Institut Agama Islam (IAI) Guru Kapuh Ibnu Atha’illah (GHIBTA). Kedua, Tahap Growing tahun 2032 menuju Universitas yang unggul dalam menghasilkan Ulama, Umaro dan Cendekiawan Muslim Dunia.
D13: Skor rumusan tujuan yang akan dicapai (0 - 4) | E13: 3 | F13: =IF(E13>4,"Salah isi","")
D14: Skor tonggak-tonggak pencapaian (0 - 4) | E14: 3 | F14: =IF(E14>4,"Salah isi","")
D15: Rata-rata | E15: 3
C16: Skor | E16: 3
A18: Penilaian butir no. 3 dilakukan oleh evaluator bidang hukum
A19: 3 | B19: 2.1.1 | C19: Badan penyelenggara (yayasan, persyarikatan, perkumpulan, paguyuban, ormas) memiliki akta notaris tentang pendirian atau perubahan badan penyelenggara tersebut. Persyaratan akta notaris untuk pendirian atau perubahan bentuk perguruan tinggi: a. Salinan akta notaris telah dilegalisasi (pernyataan sesuai dengan aslinya) oleh notaris dengan ‘cap basah’; b. Akta notaris tersebut mencantumkan ‘mendirikan perguruan tinggi’ atau istilah lain yang sejenis sebagai tujuan pendirian badan penyelenggara tersebut; c. Semua akta notaris tentang perubahan badan penyelenggara (jika badan penyelenggara melakukan perubahan badan penyelenggara) yang dapat menunjukkan hubungan antar akta notaris yang runtut. | E19: Ya | G19: Penyelenggara Institut Agama Islam (IAI) Guru Kapuh Ibnu Atha’illah (GIBTHA) adalah Lembaga Pendidikan Yayasan Ibnu Athaillah Indonesia dengan telah terdaftar di Notaris MARIA SEPTIANI SOFIA, SH., M.KN. tercatat SK. MENKEH & HAM RI No AHU-08705.50.10.2014. TANGGAL 06 NOVEMBER 2014
D20: Pilih "Ya" jika dokumen telah dilegalisasi, tujuan pendirian menyebutkan tujuan penyelenggaraan pendidikan, ada kesinambungan akta apabila terjadi perubahan yayasan. | E20: Ya
D21: Pilih "Tidak" jika dokumen tidak dilegalisasi dan/atau tidak menyebutkan tujuan penyelenggaraan pendidikan, dan/atau kesinambungan akta apabila terjadi perubahan yayasan. | E21: Tidak
C22: =IF(E22=4,"SYARAT MUTLAK TERPENUHI","SYARAT MUTLAK TIDAK TERPENUHI") -> SYARAT MUTLAK TERPENUHI | E22: =IF(E19="Ya",4,0) -> 4
A24: Penilaian butir no. 4 dilakukan oleh evaluator bidang hukum
A25: 4 | B25: 2.1.2 | C25: Badan penyelenggara telah memiliki: a. Surat keputusan pejabat berwenang (a.l.: Kemenkumham; Berita Negara) tentang pengesahan badan penyelenggara sebagai badan hukum, yang: 1) mencantumkan Nomor akta notaris pendirian badan penyelenggara yang cocok dengan Nomor akta notaris sebagaimana tercantum dalam Akta Notaris pendirian badan penyelenggara ybs.; dan 2) mencantumkan Nama badan penyelenggara yang cocok dengan Nama badan penyelenggara sebagaimana tercantum dalam akta notaris pendirian badan penyelenggara ybs; dan/atau b. Surat dari pejabat berwenang (a.l.: Kemenkumham) tentang pencatatan penyesuaian dengan peraturan perundang-undangan atau perubahan susunan pengurus badan penyelenggara. Salinan dokumen pada huruf a dan huruf b telah dilegalisasi (pernyataan sesuai dengan aslinya) oleh notaris dengan ‘cap basah’. | E25: Ya | G25: Badan Penyelenggara telah memiliki Surat Keputusan Pejabat Berwenang daro Kemenkumham melelui Notaris: MARIA SEPTIANI SOFIA, SH., M.KN. NOTARIS. PPAT, SK. MENKEH & HAM RI No. AHU-08705.50.10.2014. TANGGAL 06 NOVEMBER 2014 PENGESAHAN PENDIRIAN YAYASAN IBNU ATHA’ILLAH TANGGAL : 06 November 2014. Pada Pasal 3 disebutkan: Yayasan berberak pada bidang Pendidikan meliputi: Mendirikan Menyelenggarakan lembaga-lembaga pendidikan yang bersifat formal dan nonformal meliputi jenjang pendidikan pra-sekolah sampai tingkat perguruan tinggi atau pascasarjana
D26: Pilih "Ya" jika dokumen dilegalisasi dan kecocokan nomor akta yang tercantum di akta notaris dan nomor akta yang tercantum di SK atau surat pernyataan dan Kemkumham. | E26: Ya
D27: Pilih "Tidak" jika dokumen tidak dilegalisasi dan tidak terdapat kecocokan nomor akta yang tercantum di akta notaris dan nomor akta yang tercantum di SK atau surat pernyataan dan Kemkumham. | E27: Tidak
C28: =IF(E28=4,"SYARAT MUTLAK TERPENUHI","SYARAT MUTLAK TIDAK TERPENUHI") -> SYARAT MUTLAK TERPENUHI | E28: =IF(E25="Ya",4,0) -> 4
A30: 5 | B30: 2.2.1 | C30: Perguruan Tinggi memiliki rancangan tata pamong yang memungkinkan terlaksananya prinsip-prinsip tata pamong secara konsisten, terutama yang terkait dengan pelaku tata pamong dan sistem pengelolaan yang baik (instrumen, perangkat pendukung, kebijakan dan peraturan, serta kode etik). | E30: 3 | F30: =IF(E30>4,"Salah isi","") | G30: Rancangan tata pamong yang akan diberlakukan Institut Agama Islam (IAI) Guru Kapuh Ibnu Atha’illah (GIBTHA) bertujuan untuk membangun sistem pengelolaan yang kredibel, transparan, akuntabel, bertanggung jawab, dan adil, sesuai dengan prinsip-prinsip good university governance (GUG); indikator yg dapat diuraikan tentang pelaksanaan tata pemong kredibel terlihat dari: (1) Kredible, terlihat seluruh proses manajerial dan akademik harus didukung oleh basis empiris (evidence-based) dan justifikasi normatif. (2) Transparan, tercerrmin pada eterbukaan informasi publik (misalnya, laporan keuangan, kebijakan SDM, dan kriteria penerimaan) tetapi juga artikulasi yang eksplisit mengenai mekanisme pengambilan keputusan. (3) Akuntable, tercermin adanya kebijakan yang jelas dan keterbukaan terhadap proses pengambilan keputusan. (4) Bertanggung jawab: secara kelembagaan IAI memiliki alur pendistribusian kerja yg sudah memada. Pilar ini bertugas memastikan institusi tetap mematuhi hukum dan bertanggung jawab secara etis. IPT harus berjalan sesuai dengan aturan yang berlaku di negara, serta lebih dari itu, menggabungkan prinsip Tanggung Jawab Sosial Institusi (TSI) atau Corporate Social Responsibility (CSR), dan (5) Adil; tercermin adanya kesetaraan perlakuan dan objektivitas dalam interaksi antara institusi dengan seluruh civitas academica dan mitra. Ini diwujudkan melalui prosedur yang imparsial dalam pengelolaan sumber daya manusia, pengadaan barang/jasa, dan penentuan hak serta kewajiban.
C31: 4 | D31: Memenuhi lima pilar: kredibel, transparan, akuntabel, bertanggung jawab, dan adil.
C32: 3 | D32: Memenuhi empat dari lima pilar: kredibel, transparan, akuntabel, bertanggung jawab, dan adil.
C33: 2 | D33: Memenuhi tiga dari lima pilar: kredibel, transparan, akuntabel, bertanggung jawab, dan adil.
C34: 1 | D34: Memenuhi satu atau dua dari lima pilar: kredibel, transparan, akuntabel, bertanggung jawab, dan adil.
C35: 0 | D35: PT tidak memenuhi rancangan tata pamong.
C36: Skor | E36: =IF(E30>4,"Salah Isi", E30) -> 3
A38: 6 | B38: 2.2.2 | C38: Rancangan struktur organisasi yang disesuaikan dengan kebutuhan penyelenggaraan dan pengembangan perguruan tinggi yang bermutu serta menjamin pelaksanaan otonomi perguruan tinggi. Unsur dalam struktur organisasi: (1) penyusun kebijakan, (2) pelaksana akademik, (3) pengawas dan penjaminan mutu, (4) penunjang akademik atau sumber belajar, dan (5) pelaksana administrasi atau tata usaha. | E38: 3 | F38: =IF(E38>4,"Salah isi","") | G38: Terdapat gambaran jelas tentang rancangan struktur organisasi IAI GIBTHA terdiri dari: 1) Rektor, 2) Wakil Rektor 123, sebagai Penyusun Kebijakan; 3) Ketua Prodi dan Sekretaris Prodi sebagai pelaksana akademik; 4) LPM (Lembaga Penjaminan Mutu): sebagai pengawas dan penjamin mutu IAI, 5) Perpustakaan sebagai Penunjang Akademik/ Sumber Belajar, 6) Biro keuangan, Biro administrasi sebagai pelaksana administrasi. Ada penjelasan secara detail tentang jobdescription untuk masing-masing unit tersebut.
C39: 4 | D39: Rancangan struktur organisasi pada 5 (lima) fungsi unsur dan dilengkapi dengan deskripsi tertulis yang jelas tentang tugas, fungsi, wewenang, dan tanggung jawab, serta terlaksananya otonomi dengan sangat baik.
C40: 3 | D40: Rancangan struktur organisasi pada 4 (empat) fungsi unsur yang dilengkapi dengan deskripsi tertulis yang jelas tentang tugas, fungsi, wewenang, dan tanggung jawab.
C41: 2 | D41: Mempunyai 3 (tiga) fungsi unsur pertama yang dilengkapi dengan deskripsi tertulis yang jelas tentang tugas, fungsi, wewenang, dan tanggung jawab.
C42: 1 | D42: Tidak memiliki kelengkapan 3 (tiga) fungsi unsur pertama.
C43: 0 | D43: Tidak ada Skor kurang dari 1.
C44: Skor | E44: =IF(OR(E38<1,E38>4),"Salah Isi",E38) -> 3
A46: 7 | B46: 2.3.1 | C46: Perguruan tinggi memiliki rancangan dokumen sistem pengelolaan yang mencakup analisis jabatan, uraian tugas, prosedur kerja, serta program pengembangan kompetensi manajerial yang secara keseluruhan akan menjamin terjadinya proses pengelolaan yang efektif dan efisien di setiap unit kerja. | E46: 3 | F46: =IF(E46>4,"Salah isi","") | G46: Terdapat penjelasan secara baik dan memadai tentang IAI GHIBTA memiliki rancangan dokumen sistem pengelolaan yang mencakup (1) analisis jabatan dari setiap pengelola yg terpangpang dalam struktur organisasi, (2) uraian tugas lengkap dari setiap unsur yg ada, dan (3) prosedur kerja yg menggambarkan adanya hubungan timbal balik kerja antara satu unit dg unit lainnya, atasan bawahan. Rancangan program pengembangan kompetensi manajerial berupa: Peningkatan kompetensi manajerial dilakukan dengan mengacu kepada SK Yayasan. Program pengembangan meliputi kegiatan berikut: 1) Program Peningkatan Kompetensi manajerial Pimpinan; khusus untuk peningkatan kompetensi diberikan kepada unsur pimpinan untuk semua unit kerja di lingkungan IAI; 2) Peningkatan manajemen sumber daya manusia, 3) Peningkatan manajemen keuangan, dan 4) Peningkatan manajemen sarana prasarana.
...

Sheet F1
A1: FORMAT 1. PENILAIAN INSTRUMEN AKREDITASI INSTITUSI PERGURUAN TINGGI BARU
A3: Penilaian Perorangan
A5: Nama Badan Penyelenggara: | D5: =Menu!H6 -> Yayasan Ibnu Atha’illah
A6: Nama Asesor: | D6: Prof.Dr. Ramdani Wahyu Suurie, M.Ag.,M.Si
A7: Kode Panel | D7: =Menu!H10 -> 0
A8: Tanggal Penilaian | D8: =Menu!F20 -> 12 Mei 2026
A10: No. | B10: No. Butir | C10: Aspek Penilaian | D10: Informasi dari Instrumen | E10: Skor
A11: 1 | B11: =hitung_F1!B4 -> 1.1 | C11: =hitung_F1!C4 -> Kejelasan, kerealistikan, dan keterkaitan antar visi, misi, tujuan dan sasaran perguruan tinggi yang akan didirikan, dan pemangku kepentingan yang terlibat. | D11: =hitung_F1!G4 -> Penyusunan Visi, Misi, Tujuan, dan Sasaran Pendirian Institut Agama Islam (IAI) Guru Kapuh Ibnu Atha’illah (GHIBTA) dilakukan berdasarkan kajian terhadap tantangan serta kebutuhan yang muncul baik dari lingkungan eksternal maupun internal lembaga. Visi IAI: Menjadi Institut Agama Islam Guru Kapuh Ibnu Atha’illah Yang Unggul dalam memadukan keimanan, nilai Qur’an, adab dan keilmuan serta melahirkan generasi yang berdaya guna bagi umat dan berjiwa entrepreneur. Dalam penyusunan sudah melibatkan pihak internal dan eksternal, spt: Pondok Pesantren (Induk/Afiliasi), Pengguna Lulusan (Alumni & Dunia Kerja), Pemerintah (Kemenag, LLDIKTI, Pemda), Masyarakat/Komunitas Lokal, dan Mitra Kerja Sama (Perguruan Tinggi, NGO & Bank Syariah). Secara konseptual sudah ada kelajalasan arah visi yg diharapkan. Visi cukup realitisk karena adanya dukungan SDM dosen tendik yg memadai, ketersedian sarpras pendukung, serta tata kelola kelembagaan yg disiapkan, Konsep Visi memiliki keterkaitan arah dg mimpi atau keinginan Yayasan, yakni melahirkan generasi unggul yg berilmu pengetahuan, berakhlak al-karimah, dan mampu mengadaptasi perkembangan zaman | E11: =hitung_F1!E10 -> 3
A12: =A11+1 -> 2 | B12: =hitung_F1!B12 -> 1.2 | C12: =hitung_F1!C12 -> Perguruan tinggi yang akan didirikan menetapkan rancangan tonggak-tonggak capaian tujuan dengan rentang waktu 5 atau 10 tahun ke depan. | D12: =hitung_F1!G12 -> Rencana Induk Pengembangan (RIP) IAI Guru Kapuh Ibnu Atha’illah (GHIBTA) 2025–2047 dijelaskan arah pengembangan lembaga menuju visi tahun 2047 dengan uraian sebagai berikut: Pertama, Tahap Forming, Established Institute. tahun 2032 IAI Guru Kapuh Ibnu Atha’illah (GHIBTA) bertransformasi menjadi Institut Agama Islam (IAI) Guru Kapuh Ibnu Atha’illah (GHIBTA). Kedua, Tahap Growing tahun 2032 menuju Universitas yang unggul dalam menghasilkan Ulama, Umaro dan Cendekiawan Muslim Dunia. | E12: =hitung_F1!E16 -> 3
A13: =A12+1 -> 3 | B13: =hitung_F1!B19 -> 2.1.1 | C13: =hitung_F1!C19 -> Badan penyelenggara (yayasan, persyarikatan, perkumpulan, paguyuban, ormas) memiliki akta notaris tentang pendirian atau perubahan badan penyelenggara tersebut. Persyaratan akta notaris untuk pendirian atau perubahan bentuk perguruan tinggi: a. Salinan akta notaris telah dilegalisasi (pernyataan sesuai dengan aslinya) oleh notaris dengan ‘cap basah’; b. Akta notaris tersebut mencantumkan ‘mendirikan perguruan tinggi’ atau istilah lain yang sejenis sebagai tujuan pendirian badan penyelenggara tersebut; c. Semua akta notaris tentang perubahan badan penyelenggara (jika badan penyelenggara melakukan perubahan badan penyelenggara) yang dapat menunjukkan hubungan antar akta notaris yang runtut. | D13: =hitung_F1!G19 -> Penyelenggara Institut Agama Islam (IAI) Guru Kapuh Ibnu Atha’illah (GIBTHA) adalah Lembaga Pendidikan Yayasan Ibnu Athaillah Indonesia dengan telah terdaftar di Notaris MARIA SEPTIANI SOFIA, SH., M.KN. tercatat SK. MENKEH & HAM RI No AHU-08705.50.10.2014. TANGGAL 06 NOVEMBER 2014 | E13: =hitung_F1!E22 -> 4
A14: =A13+1 -> 4 | B14: =hitung_F1!B25 -> 2.1.2 | C14: =hitung_F1!C25 -> Badan penyelenggara telah memiliki: a. Surat keputusan pejabat berwenang (a.l.: Kemenkumham; Berita Negara) tentang pengesahan badan penyelenggara sebagai badan hukum, yang: 1) mencantumkan Nomor akta notaris pendirian badan penyelenggara yang cocok dengan Nomor akta notaris sebagaimana tercantum dalam Akta Notaris pendirian badan penyelenggara ybs.; dan 2) mencantumkan Nama badan penyelenggara yang cocok dengan Nama badan penyelenggara sebagaimana tercantum dalam akta notaris pendirian badan penyelenggara ybs; dan/atau b. Surat dari pejabat berwenang (a.l.: Kemenkumham) tentang pencatatan penyesuaian dengan peraturan perundang-undangan atau perubahan susunan pengurus badan penyelenggara. Salinan dokumen pada huruf a dan huruf b telah dilegalisasi (pernyataan sesuai dengan aslinya) oleh notaris dengan ‘cap basah’. | D14: =hitung_F1!G25 -> Badan Penyelenggara telah memiliki Surat Keputusan Pejabat Berwenang daro Kemenkumham melelui Notaris: MARIA SEPTIANI SOFIA, SH., M.KN. NOTARIS. PPAT, SK. MENKEH & HAM RI No. AHU-08705.50.10.2014. TANGGAL 06 NOVEMBER 2014 PENGESAHAN PENDIRIAN YAYASAN IBNU ATHA’ILLAH TANGGAL : 06 November 2014. Pada Pasal 3 disebutkan: Yayasan berberak pada bidang Pendidikan meliputi: Mendirikan Menyelenggarakan lembaga-lembaga pendidikan yang bersifat formal dan nonformal meliputi jenjang pendidikan pra-sekolah sampai tingkat perguruan tinggi atau pascasarjana | E14: =hitung_F1!E28 -> 4
A15: =A14+1 -> 5 | B15: =hitung_F1!B30 -> 2.2.1 | C15: =hitung_F1!C30 -> Perguruan Tinggi memiliki rancangan tata pamong yang memungkinkan terlaksananya prinsip-prinsip tata pamong secara konsisten, terutama yang terkait dengan pelaku tata pamong dan sistem pengelolaan yang baik (instrumen, perangkat pendukung, kebijakan dan peraturan, serta kode etik). | D15: =hitung_F1!G30 -> Rancangan tata pamong yang akan diberlakukan Institut Agama Islam (IAI) Guru Kapuh Ibnu Atha’illah (GIBTHA) bertujuan untuk membangun sistem pengelolaan yang kredibel, transparan, akuntabel, bertanggung jawab, dan adil, sesuai dengan prinsip-prinsip good university governance (GUG); indikator yg dapat diuraikan tentang pelaksanaan tata pemong kredibel terlihat dari: (1) Kredible, terlihat seluruh proses manajerial dan akademik harus didukung oleh basis empiris (evidence-based) dan justifikasi normatif. (2) Transparan, tercerrmin pada eterbukaan informasi publik (misalnya, laporan keuangan, kebijakan SDM, dan kriteria penerimaan) tetapi juga artikulasi yang eksplisit mengenai mekanisme pengambilan keputusan. (3) Akuntable, tercermin adanya kebijakan yang jelas dan keterbukaan terhadap proses pengambilan keputusan. (4) Bertanggung jawab: secara kelembagaan IAI memiliki alur pendistribusian kerja yg sudah memada. Pilar ini bertugas memastikan institusi tetap mematuhi hukum dan bertanggung jawab secara etis. IPT harus berjalan sesuai dengan aturan yang berlaku di negara, serta lebih dari itu, menggabungkan prinsip Tanggung Jawab Sosial Institusi (TSI) atau Corporate Social Responsibility (CSR), dan (5) Adil; tercermin adanya kesetaraan perlakuan dan objektivitas dalam interaksi antara institusi dengan seluruh civitas academica dan mitra. Ini diwujudkan melalui prosedur yang imparsial dalam pengelolaan sumber daya manusia, pengadaan barang/jasa, dan penentuan hak serta kewajiban. | E15: =hitung_F1!E36 -> 3
A16: =A15+1 -> 6 | B16: =hitung_F1!B38 -> 2.2.2 | C16: =hitung_F1!C30 -> Perguruan Tinggi memiliki rancangan tata pamong yang memungkinkan terlaksananya prinsip-prinsip tata pamong secara konsisten, terutama yang terkait dengan pelaku tata pamong dan sistem pengelolaan yang baik (instrumen, perangkat pendukung, kebijakan dan peraturan, serta kode etik). | D16: =hitung_F1!G38 -> Terdapat gambaran jelas tentang rancangan struktur organisasi IAI GIBTHA terdiri dari: 1) Rektor, 2) Wakil Rektor 123, sebagai Penyusun Kebijakan; 3) Ketua Prodi dan Sekretaris Prodi sebagai pelaksana akademik; 4) LPM (Lembaga Penjaminan Mutu): sebagai pengawas dan penjamin mutu IAI, 5) Perpustakaan sebagai Penunjang Akademik/ Sumber Belajar, 6) Biro keuangan, Biro administrasi sebagai pelaksana administrasi. Ada penjelasan secara detail tentang jobdescription untuk masing-masing unit tersebut. | E16: =hitung_F1!E44 -> 3
A17: =A16+1 -> 7 | B17: =hitung_F1!B46 -> 2.3.1 | C17: =hitung_F1!C30 -> Perguruan Tinggi memiliki rancangan tata pamong yang memungkinkan terlaksananya prinsip-prinsip tata pamong secara konsisten, terutama yang terkait dengan pelaku tata pamong dan sistem pengelolaan yang baik (instrumen, perangkat pendukung, kebijakan dan peraturan, serta kode etik). | D17: =hitung_F1!G46 -> Terdapat penjelasan secara baik dan memadai tentang IAI GHIBTA memiliki rancangan dokumen sistem pengelolaan yang mencakup (1) analisis jabatan dari setiap pengelola yg terpangpang dalam struktur organisasi, (2) uraian tugas lengkap dari setiap unsur yg ada, dan (3) prosedur kerja yg menggambarkan adanya hubungan timbal balik kerja antara satu unit dg unit lainnya, atasan bawahan. Rancangan program pengembangan kompetensi manajerial berupa: Peningkatan kompetensi manajerial dilakukan dengan mengacu kepada SK Yayasan. Program pengembangan meliputi kegiatan berikut: 1) Program Peningkatan Kompetensi manajerial Pimpinan; khusus untuk peningkatan kompetensi diberikan kepada unsur pimpinan untuk semua unit kerja di lingkungan IAI; 2) Peningkatan manajemen sumber daya manusia, 3) Peningkatan manajemen keuangan, dan 4) Peningkatan manajemen sarana prasarana. | E17: =hitung_F1!E52 -> 3
A18: =A17+1 -> 8 | B18: =hitung_F1!B54 -> 2.3.2 | C18: =hitung_F1!C54 -> Rancangan diseminasi/laporan hasil kerja perguruan tinggi secara berkala sebagai wujud akuntabilitas publik. | D18: =hitung_F1!G54 -> Rancangan desiminasi/laporan hasil kerja PT secara berkala dirancang secara baik sebagai bukti pertanggungjawaban lembaga terhadap publik, merujuk pada: Standar Nasional Pendidikan Tinggi (SN-Dikti): Diseminasi merupakan bagian dari siklus Penetapan, Pelaksanaan, Evaluasi, Pengendalian, dan Peningkatan (PPEPP) dalam Sistem Penjaminan Mutu Internal (SPMI) perguruan tinggi, dan Peraturan Badan Akreditasi Nasional Perguruan Tinggi (BAN-PT). Dokumen laporan desiminasi antara lain: 1) Menyajikan bukti otentik kepada pemangku kepentingan (internal dan eksternal) bahwa penyelenggaraan pendidikan telah memenuhi standar mutu nasional dan internasional. 2) Evaluasi Kinerja: Mengidentifikasi kekuatan dan kelemahan institusi dengan membandingkan hasil aktual terhadap target Rencana Operasional (Renop) 2026– 2031, yang diukur melalui empat kategori indikator: Masukan, Proses, Keluaran, dan Danpak. 3) Berbasis IKU dan 9 Program Strategis sebagai landasan untuk perumusan kebijakan dan perbaikan mutu berkelanjutan. | E18: =hitung_F1!E60 -> 3
A19: =A18+1 -> 9 | B19: =hitung_F1!B65 -> 2.4.1.1 | C19: =hitung_F1!C65 -> Jumlah program studi pada perguruan tinggi baru. | D19: =hitung_F1!G65 -> Terdapat 4 PS yang diusulkan untuk menyertai usulan IAI GHIBTA Kalsel. yakni: 1) Program Studi Pendidikan Bahasa Arab (PBA), 2) Program Studi Manajemen Pendidikan Islam (MPI), 3) Program Studi Pendidikan Agama Islam (PAI), dan 4) Program Studi Ekonomi Syariah (ES). | E19: =hitung_F1!E76 -> 4
A20: =A19+1 -> 10 | B20: =hitung_F1!B79 -> 2.4.1.2 | C20: =hitung_F1!C79 -> Jumlah usulan program studi berdasarkan kelompok ilmu. | D20: =hitung_F1!G79 -> Terdapat NPS_B = Jumlah program studi dari rumpun ilmu agama: 4 PS, yakni:1) Program Studi Pendidikan Bahasa Arab (PBA), 2) Program Studi Manajemen Pendidikan Islam (MPI), 3) Program Studi Pendidikan Agama Islam (PAI), dan 4) Program Studi Ekonomi Syariah (ES). | E20: =hitung_F1!E84 -> 4
A21: =A20+1 -> 11 | B21: =hitung_F1!B87 -> 2.4.1.3 | C21: =hitung_F1!C87 -> Rasio Program Diploma terhadap Program Sarjana pada Universitas, Institut dan Sekolah Tinggi. | D21: =hitung_F1!G87 -> Terdapat NPS_B = Jumlah program studi dari rumpun ilmu agama: 4 PS, yakni: 1) Program Studi Pendidikan Bahasa Arab (PBA), 2) Program Studi Manajemen Pendidikan Islam (MPI), 3) Program Studi Pendidikan Agama Islam (PAI), dan 4) Program Studi Ekonomi Syariah (ES). | E21: =hitung_F1!E92 -> 4
A22: =A21+1 -> 12 | B22: =hitung_F1!B94 -> 2.4.2 | C22: =hitung_F1!C94 -> Akreditasi Program Studi | D22: =hitung_F1!G94 -> Terdapat NM = NPS_ijinbaru = Jumlah program studi baru yang terakreditasi minimum (berdasarkan hasil penilaian akreditasi program studi baru): 4 PS, yakni 1) Program Studi Pendidikan Bahasa Arab (PBA), 2) Program Studi Manajemen Pendidikan Islam (MPI), 3) Program Studi Pendidikan Agama Islam (PAI), dan 4) Program Studi Ekonomi Syariah (ES). | E22: =hitung_F1!E101 -> 2
A23: =A22+1 -> 13 | B23: =hitung_F1!B103 -> 2.5 | C23: =hitung_F1!C103 -> Perguruan Tinggi memiliki rancangan dokumen penjaminan mutu yang terdiri dari: (1) rancangan dokumen kebijakan mutu, (2) rancangan dokumen manual mutu, (3) rancangan dokumen standar, dan (4) rancangan dokumen formulir, yang isinya mencakup keberadaan 6 elemen sistem penjaminan mutu sebagai berikut: (1) kebijakan dan standar, (2) organisasi, (3) instrumen (manual mutu, manual prosedur, instruksi kerja), (4) implementasi, (5) monitoring dan evaluasi, dan (6) pelaporan dan tindak lanjut. | D23: =hitung_F1!G103 -> IAI GHIBTA sudah memiliki rancangan Sistem Monitoring dan Evaluasi (Monev) Berbasis unggul dalam menyatukan serta memadukan keimanan, Qur’an dan adab serta keilmuan. Sistem Monev ini dirancang dalam kerangka Sistem Penjaminan Mutu Internal (SPMI) Institut Agama Islam Guru Kapuh Ibnu Atha’illah (IAI GIBTHA) dengan siklus Penetapan, Pelaksanaan, Evaluasi (Monev), Pengendalian, dan Peningkatan (PPEPP) yang dilaksanakan secara konsisten oleh PPM. MASIH PERLU DIBUAT RNCANGAN DOKUMEN KEBIJAKAN MUTU,MANUAL MUTU, STANDAR MUTU, SOP, FORMULIR MUTU, dan IMPLEMENTASI PPEPP . | E23: =hitung_F1!E109 -> 3
A24: =A23+1 -> 14 | B24: =hitung_F1!B111 -> 2.6 | C24: =hitung_F1!C111 -> Perguruan tinggi memiliki rancangan kebijakan dan pedoman kerjasama yang menjamin tercapainya aspek: (1) mutu, (2) relevansi, (3) produktifitas, dan (4) kepuasan para pihak. | D24: =hitung_F1!G111 -> IAI GIBTHA memiliki rancangan kebijakan dan pedoman kerjasama sebagaimana tertuang dalam Surat Keputusan Rektor IAI mengenai Pedoman Kerja Sama Dalam Negeri. Pedoman ini mencakup empat tahap utama, yaitu perintisan kerja sama, pengesahan, pelaksanaan, serta monitoring dan evaluasi. Dokumen pedoman ini berfungsi memastikan mutu pelaksanaan kerja sama, kesesuaian kegiatan dengan bidang keahlian perguruan tinggi dan mitra, serta produktivitas sehingga kerja sama dapat berjalan secara berkelanjutan. | E24: =hitung_F1!E117 -> 4
A25: =A24+1 -> 15 | B25: =hitung_F1!B119 -> 3.1 | C25: =hitung_F1!C119 -> Perguruan tinggi memiliki pedoman seleksi dan rekrutmen mahasiswa baru yang meliputi unsur : (1) kebijakan, (2) kriteria, (3) prosedur, dan (4) mekanisme pengambilan keputusan. | D25: =hitung_F1!G119 -> IAI GIBTHA memiliki kebijakan tentang penerimaan mahasiwa baru yg tertuang dalam Keputusan Ketua IAI Guru Kapuh Ibnu Atha’illah (GIBTHA) tentang SOP Akademik, di dalamnya berisi tentang: (1) kebijakan, ada aturan nasional dan Statuta dan Pedoman Akademik; (2) kriteria, Kriteria seleksi mahasiswa baru, dari kriteria umum, akademik, dan non-akademik. (3) prosedur, mulai dari pendaftaran, tes, dan penetapan lulusan dijelaskan secara detail; dan (4) mekanisme pengambilan keputusan, dijelaskan secara detail. Seleksi mahasiswa dilakukan secara internal, rekrutmen calon mahasiswa IAI Guru Kapuh Ibnu Atha’illah (GIBTHA) juga dibuka bagi masyarakat umum. (Cek kembali bukti formal dokumen yg dimiliki) | E25: =hitung_F1!E109 -> 3
A26: =A25+1 -> 16 | B26: =hitung_F1!B127 -> 3.2 | C26: =hitung_F1!C127 -> Perguruan tinggi memiliki kebijakan penerimaan mahasiswa baru yang memberikan peluang kepada calon mahasiswa yang memiliki potensi akademik baik namun kurang mampu secara ekonomi dan/atau cacat fisik yang ditunjang oleh rencana penyediaan fasilitas penunjang. | D26: =hitung_F1!G127 -> IAI GIBTHA memiliki rancangan aturan tentang aturan pemberian firmasi yg diberikan pada calon mahasiswa baru. Dalam upaya mewujudkan keadilan dan pemerataan akses pendidikan tinggi, IAI berkomitmen untuk memberikan kesempatan belajar yang seluas-luasnya bagi seluruh lapisan masyarakat, baik dari kalangan mampu maupun kurang mampu. Untuk menopang kebijakan afirmasi mahasiswa, IAI GIBTHA menyiapkan skema beasiswa KIP Kuliah, IAI juga menyediakan bantuan beasiswa bagi mahasiswa berprestasi maupun mahasiswa dari keluarga kurang mampu melalui kerja sama dengan lembaga sosial milik Yayasan Ibnu Atha’illah. | E26: =hitung_F1!E133 -> 4
A27: =A26+1 -> 17 | B27: =hitung_F1!B135 -> 4.1 | C27: =hitung_F1!C135 -> Rancangan sistem pengelolaan sumber daya manusia dilaksanakan berdasarkan prinsip meritokrasi yang mencakup aspek: (1) perencanaan, (2) rekrutmen dan seleksi, (3) orientasi dan penempatan pegawai, (4) pengembangan karir dan retensi, (5) remunerasi, penghargaan dan sanksi, dan (6) pensiun dan pemutusan kerja. | D27: =hitung_F1!G135 -> IAI GIBTHA memiliki rancangan tentang sistem pengelolaan sumber daya manusia dilaksanakan berdasarkan prinsip berdasarkan pada Surat Keputusan Ketua Yayasan Ibnu Atha’illah; Surat Keputusan Ketua Institut Agama Islam Guru Kapuh Ibnu Atha’illah (IAI GIBTHA); dan Surat Keputusan Ketua mengenai pedoman pengelolaan SDM Institut Agama Islam Guru Kapuh Ibnu Atha’illah (IAI GIBTHA);. Sistem seleksi/rekrutment, penempatan, pengembangan, retensi, dan pemberhentian dosen dan tenaga kependidikan tercantum pada buku Rancangan Statuta tentang system pengelolaan sumber daya manusia, dan telah dilaksanakan secara konsisten. | E27: =hitung_F1!E141 -> 3
A28: =A27+1 -> 18 | B28: =hitung_F1!B144 -> 4.2.1 | C28: =hitung_F1!C144 -> Jumlah calon dosen tetap minimal | D28: =hitung_F1!G144 -> Terdapat NDTPS_ijinbaru = Jumlah dosen tetap pada program studi baru yang terakreditasi minimum: ada 25 orang yg disiapkan untuk 5 prodi yg diuusulkan, yakni: (1) PS Pendidikan Bahasa Arab (PBA) an. Nurul Amini, M.Pd (S2 Pendidikan Bahasa Arab UII DALWA), Nafisah, M.Pd (S2 Pendidikan Bahasa Arab UII DALWA), Fathia Qonita, M.Pd (S2 Pendidikan Bahasa Arab UII DALWA), Nurul Jannah, M.Pd (S2 Pendidikan Bahasa Arab UII DALWA), Fahrunnisa, M.Pd (S2 Pendidikan Bahasa Arab UII DALWA) . (2) PS Manajemen Pendidikan Islam an. Dr. Afifafh (S2 Manajemen Pendidikan Islam), Nurwahda Maghfiroh (S2 Manajemen Pendidikan), Sufi Hadi (S2 Manajemen Pendidikan Islam), Tasiah (S2 Manajemen Pendidikan Islam), Nurul Amini (S2.....), Nurul Jannah (S2 ......), Fachri Zulmi (S2 Ekonomi Syariah). 3) PS Ekonomi Syariah (ES), an. Dr. Ir. Syahrial Shaddiq, S.T., M.Eng., M.M., M.Si (S3 Ilmu Ekonomi UII), Dr. Fathurrahman, S. Ag, M. H (S3 Doktoral Ilmu Syariah UIN Antasari), Fachri Zulmi, S. E. I, M. H (S2 Ekonomi Sriah UIN Antasari), Sri Rozana Widya Astuty, S. E, M. E (S2 lmu Ekonomi UNLAM), Halidah. S. E, M. Pd (S2 Manajemen Pendidikan UII Dalwa). 4) PS Pendidikan Agama Islam (PAI), an. DR. Ahmad Suryadi, M. Pd. (S3 Dirasah Islamiyah Konsentras i Pendidikan dan Keguruan UIN Alauddin Makassar), Miftahul Ihsan, M. Pd. (S2 UIN Sunan Kalijaga Yogyakarta), Raudatul Jannah, M. Pd (S2 PAI UIN Antasari), Muhammad Hamdani, M. Pd (S2 PAI UIN Malang), Muhammad Ikhsan, S.Pd, M. Pd (S2 PAI UIN Antasari Banjarmasin). Semua dosen yg diusulkan berstatus sebagai Dosen Tetap dan memiliki linearitas keilmuan dg program studi yg diusulkan. | E28: =hitung_F1!E150 -> 4
A29: =A28+1 -> 19 | B29: =hitung_F1!B152 -> 4.2.2 | C29: =hitung_F1!C152 -> Jumlah calon dosen tetap | D29: =hitung_F1!G152 -> Terdapat sejumlah calon dosen tetap: 24 orang, sudah memadai dihitung dari rasio 4 PS; dilihat kualifikasi penidididikan, semua sudah S2 (Magister) dengan backgroun keilmuan yang relevan dg prodi yg diusulkan. | E29: =hitung_F1!E153 -> 4
A30: =A29+1 -> 20 | B30: =hitung_F1!B156 -> 4.2.3 | C30: =hitung_F1!C156 -> Profil dosen yang diukur berdasarkan kualifikasi akademik dan kesesuaian bidang keahlian dengan kompetensi program studi. | D30: =hitung_F1!G156 -> Dari 24 Calon DTPS yang diusulkan, ada 4 orang dosen yang berkualifikasi pendidikan Doktor (S3). | E30: =hitung_F1!E162 -> 4
A31: =A30+1 -> 21 | B31: =hitung_F1!B164 -> 4.3 | C31: =hitung_F1!C164 -> Perencanaan pengembangan SDM dosen | D31: =hitung_F1!G164 -> Ada keterangan IAI GIBTHA memiliki perencanaan pengembangan SDM Dosen meliputi: (1) Pengembangan dan Pembinaan Karir; Dalam pengembangan sumber daya manusia (dosen) mengacu pada tri dharma perguruan tinggi yaitu: Untuk studi lanjut S3 semua pengajar diberi kesempatan baik dengan biaya dari internal IAI maupun dari luar IAI sesuai dengan peraturan yang berlaku. Dalam 10 Tahun akan memberikan kesempatan pada dosen untuk kuliah S3 tiap Tahun 3-5 Dosen, sehingga dalam 10 di targetkan 60% Dosen sudah Kuliah S3. (2) Pengembangan kompetensi khusus; meliputi pembinaan intern dan ekstern melalui pimpinan prodi antara lain secara selektif dengan mempercayakan kepada dosen untuk mengkoordinir berbagai kegiatan ekstra prodi. | E31: =hitung_F1!E170 -> 3
A32: =A31+1 -> 22 | B32: =hitung_F1!B172 -> 4.4.1 | C32: =hitung_F1!C172 -> Jumlah tenaga kependidikan minimal | D32: =hitung_F1!G172 -> Terdapat NTK = Jumlah tenaga kependidikan IAI GIBTHA ada 5 orang untuk melayani 4 PS, keberadaan tendik masih minim; pemenuhan tendik mestinya disesuaikan dg kebutuhan sebagai: Pustakawaan, Laboran, Oprartor, dan Teknisi | E32: =hitung_F1!E176 -> 4
A33: =A32+1 -> 23 | B33: =hitung_F1!B178 -> 4.4.2 | C33: =hitung_F1!C178 -> Tenaga Administrasi | D33: =hitung_F1!G178 -> Terdapat A = Jumlah tenaga administrasi berkualifikasi minimum S-1: 5, semua lulusan S1 (sarjana); untuk melayani 4 PS | E33: =hitung_F1!E182 -> 4
A34: =A33+1 -> 24 | B34: =hitung_F1!B184 -> 4.4.3 | C34: =hitung_F1!C184 -> Tenaga Laboran/ Teknisi | D34: =hitung_F1!G184 -> Terdapat L = Jumlah tenaga laboran/ teknisi berkualifikasi S1/SMA: 3 orang untuk 4 PS yang diusulkan | E34: =hitung_F1!E188 -> 1.1111111
A35: =A34+1 -> 25 | B35: =hitung_F1!B190 -> 4.4.4 | C35: =hitung_F1!C190 -> Tenaga Perpustakaan | D35: =hitung_F1!G190 -> Terdapat A = Jumlah tenaga perpustakaan berkualifikasi minimum S-2: 0 orang tenaga perpustakaan. KURANG TERDESKRIPSIKAN | E35: =hitung_F1!E194 -> 2.8
A36: =A35+1 -> 26 | B36: =hitung_F1!B196 -> 5.1 | C36: =hitung_F1!C196 -> Perguruan tinggi memiliki kebijakan dan pedoman akademik yang terkait dengan standar pendidikan, yang mencakup elemen: (1) kompetensi lulusan, (2) isi pembelajaran, (3) proses pembelajaran, (4) penilaian pembelajaran, (5) dosen dan tenaga kependidikan, (6) sarana dan prasarana pembelajaran, (7) pengelolaan pembelajaran, dan (8) pembiayaan pembelajaran. | D36: =hitung_F1!G196 -> Sudah ada penjelasan normatif tentang penjelasan tentang rancangan Kebijakan dan pedoman akademik IAI GIBTHA mencakup semua elemen standar pendidikan yang dirumuskan secara lengkap dengan substansi baik, seperti: (1) kompetensi lulusan, (2) isi pembelajaran, (3) proses pembelajaran, (4) penilaian pembelajaran, (5) dosen dan tenaga kependidikan, (6) sarana dan prasarana pembelajaran, (7) pengelolaan pembelajaran, dan (8) pembiayaan pembelajaran. Penjelasannya masih normatif, karena memang belum dilaksanakan. (cek kembali saat visitasi) | E36: =hitung_F1!E202 -> 2.5
A37: =A36+1 -> 27 | B37: =hitung_F1!B204 -> 5.2 | C37: =hitung_F1!C204 -> Perguruan tinggi memiliki kebijakan, pedoman dan unit kerja yang memfasilitasi/ mengkoordinasi kegiatan perencanaan, pengembangan, dan pemutakhiran kurikulum secara berkala dan berkesinambungan, beserta rencana mekanisme monitoring dan evaluasinya. | D37: =hitung_F1!G204 -> Kebijakan IAI GIBTHA dalam pengembangan kurikulum didasarkan pada STATUTA dan Panduan Akademik IAI berdasarkan SK Nomor :............... harus mendukung terhadap pengembangan Kurikulum tingkat perguruan tinggi. Didalamnya ada penjelasan tentang rancangan: (1) kebijakan, (2) pedoman pengembangan kurikulum, dan (3) unit kerja/ fungsi organisasi yang memfasilitasi program studi untuk melakukan kegiatan pengembangan kurikulum. | E37: =hitung_F1!E210 -> 2.5
A38: =A37+1 -> 28 | B38: =hitung_F1!B212 -> 5.3 | C38: =hitung_F1!C212 -> Perguruan tinggi memiliki peraturan yang mengatur tentang suasana akademik, yang mencakup unsur: (1) kebebasan akademik, (2) kebebasan mimbar akademik, dan (3) otonomi keilmuan. | D38: =hitung_F1!G212 -> IAI GIBTHAmelaksanakan kebebasan akademik, kebebasan mimbar akademik, dan otonomi keilmuan melalui pengaturan atas jaminan pengakuan, penghormatan, dan pemenuhan hal itu secara eksplisit tertuang dalam SK ......... di dalamnya memuat Kebijakan Akademik STAI, Peraturan Akademik bidang Pendidikan, Penelitian, dan Pengabdian kepada Masyarakat, Standar Akademik, dan Renstra, didalamnya mengatur ketiga unsur suasana akademik yang dinyatakan secara jelas yang mencakup unsur: (1) kebebasan akademik, (2) kebebasan mimbar akademik, dan (3) otonomi keilmuan. Walaupun penjelasannya normatif. Masing-masing dijelaskan cukup memadai, dengan data cukup. | E38: =hitung_F1!E218 -> 2.5
A39: =A38+1 -> 29 | B39: =hitung_F1!B220 -> 6.1 | C39: =hitung_F1!C220 -> Perguruan tinggi memiliki kebijakan yang berkaitan dengan standar penelitian, yang mencakup: (1) hasil penelitian; (2) isi penelitian; (3) proses penelitian; (4) penilaian penelitian; (5) peneliti; (6) sarana dan prasarana penelitian; (7) pengelolaan penelitian; dan (8) pendanaan dan pembiayaan penelitian. | D39: =hitung_F1!G220 -> Ada penjelasan normatif IAI GIBTHA memiliki rancangan kebijakan penelitian berupa berdasarkan Buku Panduan Penelitian IAI yang dikuatkan dengan SK Ketua tentang penelitian yang mencakup semua elemen standar penelitian yang dirumuskan secara lengkap dengan substansi baik. Lembaga sudah memeiliki konsep aturanmeliputi: Rencana Induk Penelitian (RIP) dan Rencana Strategis (Renstra) Pengabdian Kepada Masyarakat, Pedoman Pelaksanaan Penelitian Dan Pengabdian Kepada Masyarakat, Penetapan Roadmap Penelitian dan Pengabdian, dan Pembentukan Kelompok Riset (cek kembali saat visitasi) | E39: =hitung_F1!E226 -> 2
A40: =A39+1 -> 30 | B40: =hitung_F1!B228 -> 7.1 | C40: =hitung_F1!C228 -> Perguruan tinggi memiliki kebijakan PkM yang berkaitan dengan standar pengabdian kepada masyarakat, yang mencakup: (1) hasil PkM; (2) isi PkM; (3) proses PkM; (4) penilaian PkM; (5) pelaksana PkM; (6) sarana dan prasarana PkM; (7) pengelolaan PkM; dan (8) pendanaan dan pembiayaan PkM. | D40: =hitung_F1!G228 -> IAI GIBTHA yang diusulkan yang memiliki rancangan kebijakan PkM berupa buku panduan pengabdian SK .......... tentang PkM yang mencakup semua elemen standar PkM yang dirumuskan secara cukup baik. Lembaga sudah memeiliki konsep aturanmeliputi: Rencana Induk Penelitian (RIP) dan Rencana Strategis (Renstra) Pengabdian Kepada Masyarakat, Pedoman Pelaksanaan Penelitian Dan Pengabdian Kepada Masyarakat, Penetapan Roadmap Penelitian dan Pengabdian, dan Pembentukan Kelompok Riset. | E40: =hitung_F1!E234 -> 2
A41: =A40+1 -> 31 | B41: =hitung_F1!B237 -> 8.1.1 | C41: =hitung_F1!C237 -> Luas lahan kampus minimal | D41: =hitung_F1!G237 -> Lahan kampus yg dimimilki IAI GIBTHA = 22142 m2, beralamat: Desa Wasah Tengah, RT 004 RW 002, Kecamatan Simpur, Kabupaten Hulu Sungai Selatan, Provinsi Kalimantan Selatan, status MILIK SENDIRI dan BELUM BERSERTIFIKAT | E41: =hitung_F1!E241 -> 4
A42: =A41+1 -> 32 | B42: =hitung_F1!B244 -> 8.1.2 | C42: =hitung_F1!C244 -> Luas lahan kampus | D42: =hitung_F1!G244 -> Lahan kampus yg dimiliki sudah sangat memadai, Berlokasi beralamat: DDesa Wasah Tengah, RT 004 RW 002, Kecamatan Simpur, Kabupaten Hulu Sungai Selatan, Provinsi Kalimantan Selatan | E42: =hitung_F1!E245 -> 3.1785
A43: =A42+1 -> 33 | B43: =hitung_F1!B248 -> 8.1.3 | C43: =hitung_F1!C248 -> Status Kepemilikan Lahan | D43: =hitung_F1!G248 -> Status tanah MILIK SENDIRI (klarifikasi saat AL) | E43: =hitung_F1!E252 -> 4
...

Sheet F3
A1: FORMAT 3. BERITA ACARA ASESMEN LAPANGAN AKREDITASI INSTITUSI PERGURUAN TINGGI BARU
A3: Pada hari Ahad tanggal 24 Mei 2026 telah dilaksanakan asesmen lapangan untuk pendirian Institusi Perguruan Tinggi atas usulan Badan Penyelenggara Yayasan Ibnu Atta'illah Hulu Sungai Selatan
A4: Dari kegiatan tersebut diperoleh informasi butir-butir instrumen yang sesuai/ tidak sesuai dengan kenyataan, dengan penjelasan sebagai tercantum di dalam daftar sebagai berikut.
A6: No. | B6: No. Butir | C6: Informasi dari Instrumen | D6: Informasi dari Instrumen setelah Diverifikasi Melalui Wawancara dan Observasi | E6: Ket.
A7: ='F1'!A11 -> 1 | B7: ='F1'!B11 -> 1.1 | C7: ='F1'!D11 -> Penyusunan Visi, Misi, Tujuan, dan Sasaran Pendirian Institut Agama Islam (IAI) Guru Kapuh Ibnu Atha’illah (GHIBTA) dilakukan berdasarkan kajian terhadap tantangan serta kebutuhan yang muncul baik dari lingkungan eksternal maupun internal lembaga. Visi IAI: Menjadi Institut Agama Islam Guru Kapuh Ibnu Atha’illah Yang Unggul dalam memadukan keimanan, nilai Qur’an, adab dan keilmuan serta melahirkan generasi yang berdaya guna bagi umat dan berjiwa entrepreneur. Dalam penyusunan sudah melibatkan pihak internal dan eksternal, spt: Pondok Pesantren (Induk/Afiliasi), Pengguna Lulusan (Alumni & Dunia Kerja), Pemerintah (Kemenag, LLDIKTI, Pemda), Masyarakat/Komunitas Lokal, dan Mitra Kerja Sama (Perguruan Tinggi, NGO & Bank Syariah). Secara konseptual sudah ada kelajalasan arah visi yg diharapkan. Visi cukup realitisk karena adanya dukungan SDM dosen tendik yg memadai, ketersedian sarpras pendukung, serta tata kelola kelembagaan yg disiapkan, Konsep Visi memiliki keterkaitan arah dg mimpi atau keinginan Yayasan, yakni melahirkan generasi unggul yg berilmu pengetahuan, berakhlak al-karimah, dan mampu mengadaptasi perkembangan zaman | D7: Data sudah dikonfirmasi: Penyusunan Visi, Misi, Tujuan, dan Sasaran Pendirian Institut Ag+A7:E60ama Islam (IAI) Guru Kapuh Ibnu Atha’illah (GHIBTA) dilakukan berdasarkan kajian terhadap tantangan serta kebutuhan yang muncul baik dari lingkungan eksternal maupun internal lembaga. Visi IAI: Menjadi Institut Agama Islam Guru Kapuh Ibnu Atha’illah Yang Unggul dalam memadukan keimanan, nilai Qur’an, adab dan keilmuan serta melahirkan generasi yang berdaya guna bagi umat dan berjiwa entrepreneur. Dalam penyusunan sudah melibatkan pihak internal dan eksternal, spt: Pondok Pesantren (Induk/Afiliasi), Pengguna Lulusan (Alumni & Dunia Kerja), Pemerintah (Kemenag, LLDIKTI, Pemda), Masyarakat/Komunitas Lokal, dan Mitra Kerja Sama (Perguruan Tinggi, NGO & Bank Syariah). Secara konseptual sudah ada kelajalasan arah visi yg diharapkan. Visi cukup realitisk karena adanya dukungan SDM dosen tendik yg memadai, ketersedian sarpras pendukung, serta tata kelola kelembagaan yg disiapkan, Konsep Visi memiliki keterkaitan arah dg mimpi atau keinginan Yayasan, yakni melahirkan generasi unggul yg berilmu pengetahuan, berakhlak al-karimah, dan mampu mengadaptasi perkembangan zaman
A8: ='F1'!A12 -> 2 | B8: ='F1'!B12 -> 1.2 | C8: ='F1'!D12 -> Rencana Induk Pengembangan (RIP) IAI Guru Kapuh Ibnu Atha’illah (GHIBTA) 2025–2047 dijelaskan arah pengembangan lembaga menuju visi tahun 2047 dengan uraian sebagai berikut: Pertama, Tahap Forming, Established Institute. tahun 2032 IAI Guru Kapuh Ibnu Atha’illah (GHIBTA) bertransformasi menjadi Institut Agama Islam (IAI) Guru Kapuh Ibnu Atha’illah (GHIBTA). Kedua, Tahap Growing tahun 2032 menuju Universitas yang unggul dalam menghasilkan Ulama, Umaro dan Cendekiawan Muslim Dunia. | D8: Data sudah dikonfirmasi: Rencana Induk Pengembangan (RIP) IAI Guru Kapuh Ibnu Atha’illah (GHIBTA) 2025–2047 dijelaskan arah pengembangan lembaga menuju visi tahun 2047 dengan uraian sebagai berikut: Pertama, Tahap Forming, Established Institute. tahun 2032 IAI Guru Kapuh Ibnu Atha’illah (GHIBTA) bertransformasi menjadi Institut Agama Islam (IAI) Guru Kapuh Ibnu Atha’illah (GHIBTA). Kedua, Tahap Growing tahun 2032 menuju Universitas yang unggul dalam menghasilkan Ulama, Umaro dan Cendekiawan Muslim Dunia.
A9: ='F1'!A13 -> 3 | B9: ='F1'!B13 -> 2.1.1 | C9: ='F1'!D13 -> Penyelenggara Institut Agama Islam (IAI) Guru Kapuh Ibnu Atha’illah (GIBTHA) adalah Lembaga Pendidikan Yayasan Ibnu Athaillah Indonesia dengan telah terdaftar di Notaris MARIA SEPTIANI SOFIA, SH., M.KN. tercatat SK. MENKEH & HAM RI No AHU-08705.50.10.2014. TANGGAL 06 NOVEMBER 2014 | D9: Data terkonfirmasi: Penyelenggara Institut Agama Islam (IAI) Guru Kapuh Ibnu Atha’illah (GIBTHA) adalah Lembaga Pendidikan Yayasan Ibnu Athaillah Indonesia dengan telah terdaftar di Notaris MARIA SEPTIANI SOFIA, SH., M.KN. tercatat SK. MENKEH & HAM RI No AHU-08705.50.10.2014. TANGGAL 06 NOVEMBER 2014
A10: ='F1'!A14 -> 4 | B10: ='F1'!B14 -> 2.1.2 | C10: ='F1'!D14 -> Badan Penyelenggara telah memiliki Surat Keputusan Pejabat Berwenang daro Kemenkumham melelui Notaris: MARIA SEPTIANI SOFIA, SH., M.KN. NOTARIS. PPAT, SK. MENKEH & HAM RI No. AHU-08705.50.10.2014. TANGGAL 06 NOVEMBER 2014 PENGESAHAN PENDIRIAN YAYASAN IBNU ATHA’ILLAH TANGGAL : 06 November 2014. Pada Pasal 3 disebutkan: Yayasan berberak pada bidang Pendidikan meliputi: Mendirikan Menyelenggarakan lembaga-lembaga pendidikan yang bersifat formal dan nonformal meliputi jenjang pendidikan pra-sekolah sampai tingkat perguruan tinggi atau pascasarjana | D10: Data sudah dikonfirmasi: Badan Penyelenggara telah memiliki Surat Keputusan Pejabat Berwenang daro Kemenkumham melelui Notaris: MARIA SEPTIANI SOFIA, SH., M.KN. NOTARIS. PPAT, SK. MENKEH & HAM RI No. AHU-08705.50.10.2014. TANGGAL 06 NOVEMBER 2014 PENGESAHAN PENDIRIAN YAYASAN IBNU ATHA’ILLAH TANGGAL : 06 November 2014. Pada Pasal 3 disebutkan: Yayasan berberak pada bidang Pendidikan meliputi: Mendirikan Menyelenggarakan lembaga-lembaga pendidikan yang bersifat formal dan nonformal meliputi jenjang pendidikan pra-sekolah sampai tingkat perguruan tinggi atau pascasarjana
A11: ='F1'!A15 -> 5 | B11: ='F1'!B15 -> 2.2.1 | C11: ='F1'!D15 -> Rancangan tata pamong yang akan diberlakukan Institut Agama Islam (IAI) Guru Kapuh Ibnu Atha’illah (GIBTHA) bertujuan untuk membangun sistem pengelolaan yang kredibel, transparan, akuntabel, bertanggung jawab, dan adil, sesuai dengan prinsip-prinsip good university governance (GUG); indikator yg dapat diuraikan tentang pelaksanaan tata pemong kredibel terlihat dari: (1) Kredible, terlihat seluruh proses manajerial dan akademik harus didukung oleh basis empiris (evidence-based) dan justifikasi normatif. (2) Transparan, tercerrmin pada eterbukaan informasi publik (misalnya, laporan keuangan, kebijakan SDM, dan kriteria penerimaan) tetapi juga artikulasi yang eksplisit mengenai mekanisme pengambilan keputusan. (3) Akuntable, tercermin adanya kebijakan yang jelas dan keterbukaan terhadap proses pengambilan keputusan. (4) Bertanggung jawab: secara kelembagaan IAI memiliki alur pendistribusian kerja yg sudah memada. Pilar ini bertugas memastikan institusi tetap mematuhi hukum dan bertanggung jawab secara etis. IPT harus berjalan sesuai dengan aturan yang berlaku di negara, serta lebih dari itu, menggabungkan prinsip Tanggung Jawab Sosial Institusi (TSI) atau Corporate Social Responsibility (CSR), dan (5) Adil; tercermin adanya kesetaraan perlakuan dan objektivitas dalam interaksi antara institusi dengan seluruh civitas academica dan mitra. Ini diwujudkan melalui prosedur yang imparsial dalam pengelolaan sumber daya manusia, pengadaan barang/jasa, dan penentuan hak serta kewajiban. | D11: Data sudah dikonfirmasi: Rancangan tata pamong yang akan diberlakukan Institut Agama Islam (IAI) Guru Kapuh Ibnu Atha’illah (GIBTHA) bertujuan untuk membangun sistem pengelolaan yang kredibel, transparan, akuntabel, bertanggung jawab, dan adil, sesuai dengan prinsip-prinsip good university governance (GUG); indikator yg dapat diuraikan tentang pelaksanaan tata pemong kredibel terlihat dari: (1) Kredible, terlihat seluruh proses manajerial dan akademik harus didukung oleh basis empiris (evidence-based) dan justifikasi normatif. (2) Transparan, tercerrmin pada eterbukaan informasi publik (misalnya, laporan keuangan, kebijakan SDM, dan kriteria penerimaan) tetapi juga artikulasi yang eksplisit mengenai mekanisme pengambilan keputusan. (3) Akuntable, tercermin adanya kebijakan yang jelas dan keterbukaan terhadap proses pengambilan keputusan. (4) Bertanggung jawab: secara kelembagaan IAI memiliki alur pendistribusian kerja yg sudah memada. Pilar ini bertugas memastikan institusi tetap mematuhi hukum dan bertanggung jawab secara etis. IPT harus berjalan sesuai dengan aturan yang berlaku di negara, serta lebih dari itu, menggabungkan prinsip Tanggung Jawab Sosial Institusi (TSI) atau Corporate Social Responsibility (CSR), dan (5) Adil; tercermin adanya kesetaraan perlakuan dan objektivitas dalam interaksi antara institusi dengan seluruh civitas academica dan mitra. Ini diwujudkan melalui prosedur yang imparsial dalam pengelolaan sumber daya manusia, pengadaan barang/jasa, dan penentuan hak serta kewajiban.
A12: ='F1'!A16 -> 6 | B12: ='F1'!B16 -> 2.2.2 | C12: ='F1'!D16 -> Terdapat gambaran jelas tentang rancangan struktur organisasi IAI GIBTHA terdiri dari: 1) Rektor, 2) Wakil Rektor 123, sebagai Penyusun Kebijakan; 3) Ketua Prodi dan Sekretaris Prodi sebagai pelaksana akademik; 4) LPM (Lembaga Penjaminan Mutu): sebagai pengawas dan penjamin mutu IAI, 5) Perpustakaan sebagai Penunjang Akademik/ Sumber Belajar, 6) Biro keuangan, Biro administrasi sebagai pelaksana administrasi. Ada penjelasan secara detail tentang jobdescription untuk masing-masing unit tersebut. | D12: Fakta Lapangan dan sesuai hasil konfirmasi: Terdapat gambaran jelas tentang rancangan struktur organisasi IAI GIBTHA terdiri dari: 1) Rektor, 2) Wakil Rektor 123, sebagai Penyusun Kebijakan; 3) Ketua Prodi dan Sekretaris Prodi sebagai pelaksana akademik; 4) LPM (Lembaga Penjaminan Mutu): sebagai pengawas dan penjamin mutu IAI, 5) Perpustakaan sebagai Penunjang Akademik/ Sumber Belajar, 6) Biro keuangan, Biro administrasi sebagai pelaksana administrasi. Ada penjelasan secara detail tentang jobdescription untuk masing-masing unit tersebut.
A13: ='F1'!A17 -> 7 | B13: ='F1'!B17 -> 2.3.1 | C13: ='F1'!D17 -> Terdapat penjelasan secara baik dan memadai tentang IAI GHIBTA memiliki rancangan dokumen sistem pengelolaan yang mencakup (1) analisis jabatan dari setiap pengelola yg terpangpang dalam struktur organisasi, (2) uraian tugas lengkap dari setiap unsur yg ada, dan (3) prosedur kerja yg menggambarkan adanya hubungan timbal balik kerja antara satu unit dg unit lainnya, atasan bawahan. Rancangan program pengembangan kompetensi manajerial berupa: Peningkatan kompetensi manajerial dilakukan dengan mengacu kepada SK Yayasan. Program pengembangan meliputi kegiatan berikut: 1) Program Peningkatan Kompetensi manajerial Pimpinan; khusus untuk peningkatan kompetensi diberikan kepada unsur pimpinan untuk semua unit kerja di lingkungan IAI; 2) Peningkatan manajemen sumber daya manusia, 3) Peningkatan manajemen keuangan, dan 4) Peningkatan manajemen sarana prasarana. | D13: Sesuai data di lapangan, Terdapat penjelasan secara baik dan memadai tentang IAI GHIBTA memiliki rancangan dokumen sistem pengelolaan yang mencakup (1) analisis jabatan dari setiap pengelola yg terpangpang dalam struktur organisasi, (2) uraian tugas lengkap dari setiap unsur yg ada, dan (3) prosedur kerja yg menggambarkan adanya hubungan timbal balik kerja antara satu unit dg unit lainnya, atasan bawahan. Rancangan program pengembangan kompetensi manajerial berupa: Peningkatan kompetensi manajerial dilakukan dengan mengacu kepada SK Yayasan. Program pengembangan meliputi kegiatan berikut: 1) Program Peningkatan Kompetensi manajerial Pimpinan; khusus untuk peningkatan kompetensi diberikan kepada unsur pimpinan untuk semua unit kerja di lingkungan IAI; 2) Peningkatan manajemen sumber daya manusia, 3) Peningkatan manajemen keuangan, dan 4) Peningkatan manajemen sarana prasarana.
A14: ='F1'!A18 -> 8 | B14: ='F1'!B18 -> 2.3.2 | C14: ='F1'!D18 -> Rancangan desiminasi/laporan hasil kerja PT secara berkala dirancang secara baik sebagai bukti pertanggungjawaban lembaga terhadap publik, merujuk pada: Standar Nasional Pendidikan Tinggi (SN-Dikti): Diseminasi merupakan bagian dari siklus Penetapan, Pelaksanaan, Evaluasi, Pengendalian, dan Peningkatan (PPEPP) dalam Sistem Penjaminan Mutu Internal (SPMI) perguruan tinggi, dan Peraturan Badan Akreditasi Nasional Perguruan Tinggi (BAN-PT). Dokumen laporan desiminasi antara lain: 1) Menyajikan bukti otentik kepada pemangku kepentingan (internal dan eksternal) bahwa penyelenggaraan pendidikan telah memenuhi standar mutu nasional dan internasional. 2) Evaluasi Kinerja: Mengidentifikasi kekuatan dan kelemahan institusi dengan membandingkan hasil aktual terhadap target Rencana Operasional (Renop) 2026– 2031, yang diukur melalui empat kategori indikator: Masukan, Proses, Keluaran, dan Danpak. 3) Berbasis IKU dan 9 Program Strategis sebagai landasan untuk perumusan kebijakan dan perbaikan mutu berkelanjutan. | D14: Secara Fakta di lapangan: Rancangan desiminasi/laporan hasil kerja PT secara berkala dirancang secara baik sebagai bukti pertanggungjawaban lembaga terhadap publik, merujuk pada: Standar Nasional Pendidikan Tinggi (SN-Dikti): Diseminasi merupakan bagian dari siklus Penetapan, Pelaksanaan, Evaluasi, Pengendalian, dan Peningkatan (PPEPP) dalam Sistem Penjaminan Mutu Internal (SPMI) perguruan tinggi, dan Peraturan Badan Akreditasi Nasional Perguruan Tinggi (BAN-PT). Dokumen laporan desiminasi antara lain: 1) Menyajikan bukti otentik kepada pemangku kepentingan (internal dan eksternal) bahwa penyelenggaraan pendidikan telah memenuhi standar mutu nasional dan internasional. 2) Evaluasi Kinerja: Mengidentifikasi kekuatan dan kelemahan institusi dengan membandingkan hasil aktual terhadap target Rencana Operasional (Renop) 2026– 2031, yang diukur melalui empat kategori indikator: Masukan, Proses, Keluaran, dan Danpak. 3) Berbasis IKU dan 9 Program Strategis sebagai landasan untuk perumusan kebijakan dan perbaikan mutu berkelanjutan.
A15: ='F1'!A19 -> 9 | B15: ='F1'!B19 -> 2.4.1.1 | C15: ='F1'!D19 -> Terdapat 4 PS yang diusulkan untuk menyertai usulan IAI GHIBTA Kalsel. yakni: 1) Program Studi Pendidikan Bahasa Arab (PBA), 2) Program Studi Manajemen Pendidikan Islam (MPI), 3) Program Studi Pendidikan Agama Islam (PAI), dan 4) Program Studi Ekonomi Syariah (ES). | D15: Fakta Lapangan: Terdapat 4 PS yang diusulkan untuk menyertai usulan IAI GHIBTA Kalsel. yakni: 1) Program Studi Pendidikan Bahasa Arab (PBA), 2) Program Studi Manajemen Pendidikan Islam (MPI), 3) Program Studi Pendidikan Agama Islam (PAI), dan 4) Program Studi Ekonomi Syariah (ES).
A16: ='F1'!A20 -> 10 | B16: ='F1'!B20 -> 2.4.1.2 | C16: ='F1'!D20 -> Terdapat NPS_B = Jumlah program studi dari rumpun ilmu agama: 4 PS, yakni:1) Program Studi Pendidikan Bahasa Arab (PBA), 2) Program Studi Manajemen Pendidikan Islam (MPI), 3) Program Studi Pendidikan Agama Islam (PAI), dan 4) Program Studi Ekonomi Syariah (ES). | D16: Fakta Lapangan: Terdapat NPS_B = Jumlah program studi dari rumpun ilmu agama: 4 PS, yakni:1) Program Studi Pendidikan Bahasa Arab (PBA), 2) Program Studi Manajemen Pendidikan Islam (MPI), 3) Program Studi Pendidikan Agama Islam (PAI), dan 4) Program Studi Ekonomi Syariah (ES).
A17: ='F1'!A21 -> 11 | B17: ='F1'!B21 -> 2.4.1.3 | C17: ='F1'!D21 -> Terdapat NPS_B = Jumlah program studi dari rumpun ilmu agama: 4 PS, yakni: 1) Program Studi Pendidikan Bahasa Arab (PBA), 2) Program Studi Manajemen Pendidikan Islam (MPI), 3) Program Studi Pendidikan Agama Islam (PAI), dan 4) Program Studi Ekonomi Syariah (ES). | D17: Fakta Lapangan: Terdapat NPS_B = Jumlah program studi dari rumpun ilmu agama: 4 PS, yakni: 1) Program Studi Pendidikan Bahasa Arab (PBA), 2) Program Studi Manajemen Pendidikan Islam (MPI), 3) Program Studi Pendidikan Agama Islam (PAI), dan 4) Program Studi Ekonomi Syariah (ES).
A18: ='F1'!A22 -> 12 | B18: ='F1'!B22 -> 2.4.2 | C18: ='F1'!D22 -> Terdapat NM = NPS_ijinbaru = Jumlah program studi baru yang terakreditasi minimum (berdasarkan hasil penilaian akreditasi program studi baru): 4 PS, yakni 1) Program Studi Pendidikan Bahasa Arab (PBA), 2) Program Studi Manajemen Pendidikan Islam (MPI), 3) Program Studi Pendidikan Agama Islam (PAI), dan 4) Program Studi Ekonomi Syariah (ES). | D18: Fakta Lapangan: Terdapat NM = NPS_ijinbaru = Jumlah program studi baru yang terakreditasi minimum (berdasarkan hasil penilaian akreditasi program studi baru): 4 PS, yakni 1) Program Studi Pendidikan Bahasa Arab (PBA), 2) Program Studi Manajemen Pendidikan Islam (MPI), 3) Program Studi Pendidikan Agama Islam (PAI), dan 4) Program Studi Ekonomi Syariah (ES).
... A58: ='F1'!A62 -> 52 | B58: ='F1'!B62 -> 9.2.2.2 | C58: ='F1'!D62 -> IAI GIBTHA memiliki rencana penggunaan dana yang realistik untuk penyelenggaraan proses pembelajaran, penelitian dan PkM seluruh program studi dan rencana investasi yang memadai selama minimal 3 tahun ke depan | D58: Data Terkonfirmasi: IAI GIBTHA memiliki rencana penggunaan dana yang realistik untuk penyelenggaraan proses pembelajaran, penelitian dan PkM seluruh program studi dan rencana investasi yang memadai selama minimal 3 tahun ke depan
A60: Berita acara asesmen lapangan ini ditandatangani oleh asesor dan pimpinan badan penyelenggara.
D62: Sugai Hulu Selatan, 24 Mei 2026
A64: Pimpinan Badan Penyelenggara | D64: Asesor
A65: Ketua Yayasan Ibnu Atha’illah
D68: 1. Prof. Dr. Ramdani Wahyu Sururie
A73: H. Akhmad Sukeran, S.Pd | D73: 2. Prof. Dr.Fauzan, MA

Sheet F4
A1: FORMAT 4. PENILAIAN AKHIR AKREDITASI INSTITUSI PERGURUAN TINGGI BARU
A3: Penilaian Tim
A5: Nama Badan Penyelenggara: | F5: =Menu!H6 -> Yayasan Ibnu Atha’illah
A6: Kode Panel: | F6: =Menu!H10 -> 0
A7: Tanggal Penilaian: | F7: =Menu!R24 -> 24 Mei 2026
A9: Berdasarkan penilaian yang dilakukan pada kegiatan asesmen kecukupan dan asesmen lapangan, disampaikan penilaian akhir akreditasi institusi perguruan tinggi baru yang disajikan pada tabel berikut.
A11: No. | B11: No. Butir | C11: Penilaian | G11: Penjelasan/Dasar Penilaian yang Diperoleh dari Dokumen Borang, Wawancara, dan Observasi | H11: Rekomendasi Pendirian
C12: Asr-1 | D12: Asr-2 | F12: Nilai Akhir
C13: Asr1 | D13: Asr2 | E13: Asr3 | F13: Nilai Akhir
A14: ='F1'!A11 -> 1 | B14: ='F1'!B11 -> 1.1 | C14: 3.5 | F14: =AVERAGE(C14:E14) -> 3.5 | G14: ='F3'!D7 -> Data sudah dikonfirmasi: Penyusunan Visi, Misi, Tujuan, dan Sasaran Pendirian Institut Ag+A7:E60ama Islam (IAI) Guru Kapuh Ibnu Atha’illah (GHIBTA) dilakukan berdasarkan kajian terhadap tantangan serta kebutuhan yang muncul baik dari lingkungan eksternal maupun internal lembaga. Visi IAI: Menjadi Institut Agama Islam Guru Kapuh Ibnu Atha’illah Yang Unggul dalam memadukan keimanan, nilai Qur’an, adab dan keilmuan serta melahirkan generasi yang berdaya guna bagi umat dan berjiwa entrepreneur. Dalam penyusunan sudah melibatkan pihak internal dan eksternal, spt: Pondok Pesantren (Induk/Afiliasi), Pengguna Lulusan (Alumni & Dunia Kerja), Pemerintah (Kemenag, LLDIKTI, Pemda), Masyarakat/Komunitas Lokal, dan Mitra Kerja Sama (Perguruan Tinggi, NGO & Bank Syariah). Secara konseptual sudah ada kelajalasan arah visi yg diharapkan. Visi cukup realitisk karena adanya dukungan SDM dosen tendik yg memadai, ketersedian sarpras pendukung, serta tata kelola kelembagaan yg disiapkan, Konsep Visi memiliki keterkaitan arah dg mimpi atau keinginan Yayasan, yakni melahirkan generasi unggul yg berilmu pengetahuan, berakhlak al-karimah, dan mampu mengadaptasi perkembangan zaman
